Workbook

Sheet to do
A1: check value definitions | B1: done
A2: build in-year value dashboard
A3: calibrate baseline | B3: done

Sheet config
A1: Configurable | D1: Fixed
A2: workstreams | B2: done | D2: 5 stage gates
A3: financial impact types | B3: done
A4: initiative tag | B4: done
A5: approval flows
A6: stage gate progression requirement / checklist

Sheet Dashboards
A1: Run rate value of completed initiatives (completed initiative = initiative in G4)
A2: Plan - locked on [selected date]
B3: =DATE(2026,7,1) -> 46204 | C3: =EDATE(B3,1) -> 46235 | D3: =EDATE(C3,1) -> 46266 | E3: =EDATE(D3,1) -> 46296 | F3: =EDATE(E3,1) -> 46327 | G3: =EDATE(F3,1) -> 46357 | H3: =EDATE(G3,1) -> 46388 | I3: =EDATE(H3,1) -> 46419 | J3: =EDATE(I3,1) -> 46447 | ... S3: =EDATE(R3,1) -> 46722
A4: Westmark Region | B4: =SUMIFS('Initiative Summary'!$O$5:$O$25,'Initiative Summary'!$C$5:$C$25,$A4,'Initiative Summary'!$K$5:$K$25,"<="&EOMONTH(B$3,0)) -> 0 | C4: =SUMIFS('Initiative Summary'!$O$5:$O$25,'Initiative Summary'!$C$5:$C$25,$A4,'Initiative Summary'!$K$5:$K$25,"<="&EOMONTH(C$3,0)) -> 0 | D4: =SUMIFS('Initiative Summary'!$O$5:$O$25,'Initiative Summary'!$C$5:$C$25,$A4,'Initiative Summary'!$K$5:$K$25,"<="&EOMONTH(D$3,0)) -> 0 | E4: =SUMIFS('Initiative Summary'!$O$5:$O$25,'Initiative Summary'!$C$5:$C$25,$A4,'Initiative Summary'!$K$5:$K$25,"<="&EOMONTH(E$3,0)) -> 0 | F4: =SUMIFS('Initiative Summary'!$O$5:$O$25,'Initiative Summary'!$C$5:$C$25,$A4,'Initiative Summary'!$K$5:$K$25,"<="&EOMONTH(F$3,0)) -> 1.76 | G4: =SUMIFS('Initiative Summary'!$O$5:$O$25,'Initiative Summary'!$C$5:$C$25,$A4,'Initiative Summary'!$K$5:$K$25,"<="&EOMONTH(G$3,0)) -> 1.84 | H4: =SUMIFS('Initiative Summary'!$O$5:$O$25,'Initiative Summary'!$C$5:$C$25,$A4,'Initiative Summary'!$K$5:$K$25,"<="&EOMONTH(H$3,0)) -> 1.84 | I4: =SUMIFS('Initiative Summary'!$O$5:$O$25,'Initiative Summary'!$C$5:$C$25,$A4,'Initiative Summary'!$K$5:$K$25,"<="&EOMONTH(I$3,0)) -> 1.84 | ... S4: =SUMIFS('Initiative Summary'!$O$5:$O$25,'Initiative Summary'!$C$5:$C$25,$A4,'Initiative Summary'!$K$5:$K$25,"<="&EOMONTH(S$3,0)) -> 4.88
A5: Eastbridge Region | B5: =SUMIFS('Initiative Summary'!$O$5:$O$25,'Initiative Summary'!$C$5:$C$25,$A5,'Initiative Summary'!$K$5:$K$25,"<="&EOMONTH(B$3,0)) -> 0 | C5: =SUMIFS('Initiative Summary'!$O$5:$O$25,'Initiative Summary'!$C$5:$C$25,$A5,'Initiative Summary'!$K$5:$K$25,"<="&EOMONTH(C$3,0)) -> 0 | D5: =SUMIFS('Initiative Summary'!$O$5:$O$25,'Initiative Summary'!$C$5:$C$25,$A5,'Initiative Summary'!$K$5:$K$25,"<="&EOMONTH(D$3,0)) -> 0 | E5: =SUMIFS('Initiative Summary'!$O$5:$O$25,'Initiative Summary'!$C$5:$C$25,$A5,'Initiative Summary'!$K$5:$K$25,"<="&EOMONTH(E$3,0)) -> 1.584 | F5: =SUMIFS('Initiative Summary'!$O$5:$O$25,'Initiative Summary'!$C$5:$C$25,$A5,'Initiative Summary'!$K$5:$K$25,"<="&EOMONTH(F$3,0)) -> 1.584 | G5: =SUMIFS('Initiative Summary'!$O$5:$O$25,'Initiative Summary'!$C$5:$C$25,$A5,'Initiative Summary'!$K$5:$K$25,"<="&EOMONTH(G$3,0)) -> 1.584 | H5: =SUMIFS('Initiative Summary'!$O$5:$O$25,'Initiative Summary'!$C$5:$C$25,$A5,'Initiative Summary'!$K$5:$K$25,"<="&EOMONTH(H$3,0)) -> 1.584 | I5: =SUMIFS('Initiative Summary'!$O$5:$O$25,'Initiative Summary'!$C$5:$C$25,$A5,'Initiative Summary'!$K$5:$K$25,"<="&EOMONTH(I$3,0)) -> 1.584 | ... S5: =SUMIFS('Initiative Summary'!$O$5:$O$25,'Initiative Summary'!$C$5:$C$25,$A5,'Initiative Summary'!$K$5:$K$25,"<="&EOMONTH(S$3,0)) -> 4.762
A6: Northpeak Region | B6: =SUMIFS('Initiative Summary'!$O$5:$O$25,'Initiative Summary'!$C$5:$C$25,$A6,'Initiative Summary'!$K$5:$K$25,"<="&EOMONTH(B$3,0)) -> 0 | C6: =SUMIFS('Initiative Summary'!$O$5:$O$25,'Initiative Summary'!$C$5:$C$25,$A6,'Initiative Summary'!$K$5:$K$25,"<="&EOMONTH(C$3,0)) -> 0 | D6: =SUMIFS('Initiative Summary'!$O$5:$O$25,'Initiative Summary'!$C$5:$C$25,$A6,'Initiative Summary'!$K$5:$K$25,"<="&EOMONTH(D$3,0)) -> 0 | E6: =SUMIFS('Initiative Summary'!$O$5:$O$25,'Initiative Summary'!$C$5:$C$25,$A6,'Initiative Summary'!$K$5:$K$25,"<="&EOMONTH(E$3,0)) -> 0 | F6: =SUMIFS('Initiative Summary'!$O$5:$O$25,'Initiative Summary'!$C$5:$C$25,$A6,'Initiative Summary'!$K$5:$K$25,"<="&EOMONTH(F$3,0)) -> 0 | G6: =SUMIFS('Initiative Summary'!$O$5:$O$25,'Initiative Summary'!$C$5:$C$25,$A6,'Initiative Summary'!$K$5:$K$25,"<="&EOMONTH(G$3,0)) -> 0.088 | H6: =SUMIFS('Initiative Summary'!$O$5:$O$25,'Initiative Summary'!$C$5:$C$25,$A6,'Initiative Summary'!$K$5:$K$25,"<="&EOMONTH(H$3,0)) -> 0.62 | I6: =SUMIFS('Initiative Summary'!$O$5:$O$25,'Initiative Summary'!$C$5:$C$25,$A6,'Initiative Summary'!$K$5:$K$25,"<="&EOMONTH(I$3,0)) -> 0.62 | ... S6: =SUMIFS('Initiative Summary'!$O$5:$O$25,'Initiative Summary'!$C$5:$C$25,$A6,'Initiative Summary'!$K$5:$K$25,"<="&EOMONTH(S$3,0)) -> 4.906
A7: Southgate Region | B7: =SUMIFS('Initiative Summary'!$O$5:$O$25,'Initiative Summary'!$C$5:$C$25,$A7,'Initiative Summary'!$K$5:$K$25,"<="&EOMONTH(B$3,0)) -> 0 | C7: =SUMIFS('Initiative Summary'!$O$5:$O$25,'Initiative Summary'!$C$5:$C$25,$A7,'Initiative Summary'!$K$5:$K$25,"<="&EOMONTH(C$3,0)) -> 0 | D7: =SUMIFS('Initiative Summary'!$O$5:$O$25,'Initiative Summary'!$C$5:$C$25,$A7,'Initiative Summary'!$K$5:$K$25,"<="&EOMONTH(D$3,0)) -> 0 | E7: =SUMIFS('Initiative Summary'!$O$5:$O$25,'Initiative Summary'!$C$5:$C$25,$A7,'Initiative Summary'!$K$5:$K$25,"<="&EOMONTH(E$3,0)) -> 0 | F7: =SUMIFS('Initiative Summary'!$O$5:$O$25,'Initiative Summary'!$C$5:$C$25,$A7,'Initiative Summary'!$K$5:$K$25,"<="&EOMONTH(F$3,0)) -> 0.092 | G7: =SUMIFS('Initiative Summary'!$O$5:$O$25,'Initiative Summary'!$C$5:$C$25,$A7,'Initiative Summary'!$K$5:$K$25,"<="&EOMONTH(G$3,0)) -> 0.092 | H7: =SUMIFS('Initiative Summary'!$O$5:$O$25,'Initiative Summary'!$C$5:$C$25,$A7,'Initiative Summary'!$K$5:$K$25,"<="&EOMONTH(H$3,0)) -> 0.092 | I7: =SUMIFS('Initiative Summary'!$O$5:$O$25,'Initiative Summary'!$C$5:$C$25,$A7,'Initiative Summary'!$K$5:$K$25,"<="&EOMONTH(I$3,0)) -> 1.441 | ... S7: =SUMIFS('Initiative Summary'!$O$5:$O$25,'Initiative Summary'!$C$5:$C$25,$A7,'Initiative Summary'!$K$5:$K$25,"<="&EOMONTH(S$3,0)) -> 3.525
A8: Total | B8: =SUM(B4:B7) -> 0 | C8: =SUM(C4:C7) -> 0 | D8: =SUM(D4:D7) -> 0 | E8: =SUM(E4:E7) -> 1.584 | F8: =SUM(F4:F7) -> 3.436 | G8: =SUM(G4:G7) -> 3.604 | H8: =SUM(H4:H7) -> 4.136 | I8: =SUM(I4:I7) -> 5.485 | ... S8: =SUM(S4:S7) -> 18.073
A10: Actual (based on actual date and value of initiatives completed, regardless of whether they were part of the plan)
B11: =DATE(2026,7,1) -> 46204 | C11: =EDATE(B11,1) -> 46235 | D11: =EDATE(C11,1) -> 46266 | E11: =EDATE(D11,1) -> 46296 | F11: =EDATE(E11,1) -> 46327 | G11: =EDATE(F11,1) -> 46357 | H11: =EDATE(G11,1) -> 46388 | I11: =EDATE(H11,1) -> 46419 | J11: =EDATE(I11,1) -> 46447 | ... S11: =EDATE(R11,1) -> 46722
A12: Westmark Region
A13: Eastbridge Region
A14: Northpeak Region
A15: Southgate Region
A16: Total | B16: =SUM(B12:B15) -> 0 | C16: =SUM(C12:C15) -> 0 | D16: =SUM(D12:D15) -> 0 | E16: =SUM(E12:E15) -> 0 | F16: =SUM(F12:F15) -> 0 | G16: =SUM(G12:G15) -> 0 | H16: =SUM(H12:H15) -> 0 | I16: =SUM(I12:I15) -> 0 | ... S16: =SUM(S12:S15) -> 0
A20: In-year value of initiatives
B21: FY26 | C21: FY27 | D21: FY28 | E21: FY29 | F21: FY30 | H21: =DATE(2026,7,1) -> 46204 | I21: =EDATE(H21,1) -> 46235 | J21: =EDATE(I21,1) -> 46266 | K21: =EDATE(J21,1) -> 46296 | L21: =EDATE(K21,1) -> 46327 | M21: =EDATE(L21,1) -> 46357 | N21: =EDATE(M21,1) -> 46388 | O21: =EDATE(N21,1) -> 46419 | P21: =EDATE(O21,1) -> 46447 | ... BI21: =EDATE(BH21,1) -> 47818
A22: Plan - locked on [selected date - based on initiatives in G3 then]
A23: Revenue (USD m)
A24: Westmark Region | B24: =SUMIFS(Benefits!$S:$S,Benefits!$E:$E,"Revenue",Benefits!$F:$F,"USD",Benefits!$D:$D,"Plan Base",Benefits!$CS:$CS,$A24) -> 0.52 | C24: =SUMIFS(Benefits!$T:$T,Benefits!$E:$E,"Revenue",Benefits!$F:$F,"USD",Benefits!$D:$D,"Plan Base",Benefits!$CS:$CS,$A24) -> 2.32 | D24: =SUMIFS(Benefits!$U:$U,Benefits!$E:$E,"Revenue",Benefits!$F:$F,"USD",Benefits!$D:$D,"Plan Base",Benefits!$CS:$CS,$A24) -> 3.96 | E24: =SUMIFS(Benefits!$V:$V,Benefits!$E:$E,"Revenue",Benefits!$F:$F,"USD",Benefits!$D:$D,"Plan Base",Benefits!$CS:$CS,$A24) -> 3.96 | F24: =SUMIFS(Benefits!$W:$W,Benefits!$E:$E,"Revenue",Benefits!$F:$F,"USD",Benefits!$D:$D,"Plan Base",Benefits!$CS:$CS,$A24) -> 3.96 | H24: =SUMIFS(Benefits!$AD:$AD,Benefits!$E:$E,"Revenue",Benefits!$F:$F,"USD",Benefits!$D:$D,"Plan Base",Benefits!$CS:$CS,$A24) -> 0 | I24: =SUMIFS(Benefits!$AE:$AE,Benefits!$E:$E,"Revenue",Benefits!$F:$F,"USD",Benefits!$D:$D,"Plan Base",Benefits!$CS:$CS,$A24) -> 0 | J24: =SUMIFS(Benefits!$AF:$AF,Benefits!$E:$E,"Revenue",Benefits!$F:$F,"USD",Benefits!$D:$D,"Plan Base",Benefits!$CS:$CS,$A24) -> 0 | K24: =SUMIFS(Benefits!$AG:$AG,Benefits!$E:$E,"Revenue",Benefits!$F:$F,"USD",Benefits!$D:$D,"Plan Base",Benefits!$CS:$CS,$A24) -> 0 | L24: =SUMIFS(Benefits!$AH:$AH,Benefits!$E:$E,"Revenue",Benefits!$F:$F,"USD",Benefits!$D:$D,"Plan Base",Benefits!$CS:$CS,$A24) -> 0 | M24: =SUMIFS(Benefits!$AI:$AI,Benefits!$E:$E,"Revenue",Benefits!$F:$F,"USD",Benefits!$D:$D,"Plan Base",Benefits!$CS:$CS,$A24) -> 0.52 | N24: =SUMIFS(Benefits!$AJ:$AJ,Benefits!$E:$E,"Revenue",Benefits!$F:$F,"USD",Benefits!$D:$D,"Plan Base",Benefits!$CS:$CS,$A24) -> 0.091666667 | O24: =SUMIFS(Benefits!$AK:$AK,Benefits!$E:$E,"Revenue",Benefits!$F:$F,"USD",Benefits!$D:$D,"Plan Base",Benefits!$CS:$CS,$A24) -> 0.091666667 | P24: =SUMIFS(Benefits!$AL:$AL,Benefits!$E:$E,"Revenue",Benefits!$F:$F,"USD",Benefits!$D:$D,"Plan Base",Benefits!$CS:$CS,$A24) -> 0.091666667 | Q24: =SUMIFS(Benefits!$AM:$AM,Benefits!$E:$E,"Revenue",Benefits!$F:$F,"USD",Benefits!$D:$D,"Plan Base",Benefits!$CS:$CS,$A24) -> 0.13611111 | R24: =SUMIFS(Benefits!$AN:$AN,Benefits!$E:$E,"Revenue",Benefits!$F:$F,"USD",Benefits!$D:$D,"Plan Base",Benefits!$CS:$CS,$A24) -> 0.13611111 | S24: =SUMIFS(Benefits!$AO:$AO,Benefits!$E:$E,"Revenue",Benefits!$F:$F,"USD",Benefits!$D:$D,"Plan Base",Benefits!$CS:$CS,$A24) -> 0.13611111 | T24: =SUMIFS(Benefits!$AP:$AP,Benefits!$E:$E,"Revenue",Benefits!$F:$F,"USD",Benefits!$D:$D,"Plan Base",Benefits!$CS:$CS,$A24) -> 0.13611111 | U24: =SUMIFS(Benefits!$AQ:$AQ,Benefits!$E:$E,"Revenue",Benefits!$F:$F,"USD",Benefits!$D:$D,"Plan Base",Benefits!$CS:$CS,$A24) -> 0.13611111 | V24: =SUMIFS(Benefits!$AR:$AR,Benefits!$E:$E,"Revenue",Benefits!$F:$F,"USD",Benefits!$D:$D,"Plan Base",Benefits!$CS:$CS,$A24) -> 0.13611111 | W24: =SUMIFS(Benefits!$AS:$AS,Benefits!$E:$E,"Revenue",Benefits!$F:$F,"USD",Benefits!$D:$D,"Plan Base",Benefits!$CS:$CS,$A24) -> 0.13611111 | X24: =SUMIFS(Benefits!$AT:$AT,Benefits!$E:$E,"Revenue",Benefits!$F:$F,"USD",Benefits!$D:$D,"Plan Base",Benefits!$CS:$CS,$A24) -> 0.13611111 | Y24: =SUMIFS(Benefits!$AU:$AU,Benefits!$E:$E,"Revenue",Benefits!$F:$F,"USD",Benefits!$D:$D,"Plan Base",Benefits!$CS:$CS,$A24) -> 0.95611111 | Z24: =SUMIFS(Benefits!$AV:$AV,Benefits!$E:$E,"Revenue",Benefits!$F:$F,"USD",Benefits!$D:$D,"Plan Base",Benefits!$CS:$CS,$A24) -> 0.33 | AA24: =SUMIFS(Benefits!$AW:$AW,Benefits!$E:$E,"Revenue",Benefits!$F:$F,"USD",Benefits!$D:$D,"Plan Base",Benefits!$CS:$CS,$A24) -> 0.33 | AB24: =SUMIFS(Benefits!$AX:$AX,Benefits!$E:$E,"Revenue",Benefits!$F:$F,"USD",Benefits!$D:$D,"Plan Base",Benefits!$CS:$CS,$A24) -> 0.33 | AC24: =SUMIFS(Benefits!$AY:$AY,Benefits!$E:$E,"Revenue",Benefits!$F:$F,"USD",Benefits!$D:$D,"Plan Base",Benefits!$CS:$CS,$A24) -> 0.33 | AD24: =SUMIFS(Benefits!$AZ:$AZ,Benefits!$E:$E,"Revenue",Benefits!$F:$F,"USD",Benefits!$D:$D,"Plan Base",Benefits!$CS:$CS,$A24) -> 0.33 | AE24: =SUMIFS(Benefits!$BA:$BA,Benefits!$E:$E,"Revenue",Benefits!$F:$F,"USD",Benefits!$D:$D,"Plan Base",Benefits!$CS:$CS,$A24) -> 0.33 | AF24: =SUMIFS(Benefits!$BB:$BB,Benefits!$E:$E,"Revenue",Benefits!$F:$F,"USD",Benefits!$D:$D,"Plan Base",Benefits!$CS:$CS,$A24) -> 0.33 | AG24: =SUMIFS(Benefits!$BC:$BC,Benefits!$E:$E,"Revenue",Benefits!$F:$F,"USD",Benefits!$D:$D,"Plan Base",Benefits!$CS:$CS,$A24) -> 0.33 | AH24: =SUMIFS(Benefits!$BD:$BD,Benefits!$E:$E,"Revenue",Benefits!$F:$F,"USD",Benefits!$D:$D,"Plan Base",Benefits!$CS:$CS,$A24) -> 0.33 | AI24: =SUMIFS(Benefits!$BE:$BE,Benefits!$E:$E,"Revenue",Benefits!$F:$F,"USD",Benefits!$D:$D,"Plan Base",Benefits!$CS:$CS,$A24) -> 0.33 | AJ24: =SUMIFS(Benefits!$BF:$BF,Benefits!$E:$E,"Revenue",Benefits!$F:$F,"USD",Benefits!$D:$D,"Plan Base",Benefits!$CS:$CS,$A24) -> 0.33 | AK24: =SUMIFS(Benefits!$BG:$BG,Benefits!$E:$E,"Revenue",Benefits!$F:$F,"USD",Benefits!$D:$D,"Plan Base",Benefits!$CS:$CS,$A24) -> 0.33 | AL24: =SUMIFS(Benefits!$BH:$BH,Benefits!$E:$E,"Revenue",Benefits!$F:$F,"USD",Benefits!$D:$D,"Plan Base",Benefits!$CS:$CS,$A24) -> 0.33 | AM24: =SUMIFS(Benefits!$BI:$BI,Benefits!$E:$E,"Revenue",Benefits!$F:$F,"USD",Benefits!$D:$D,"Plan Base",Benefits!$CS:$CS,$A24) -> 0.33 | AN24: =SUMIFS(Benefits!$BJ:$BJ,Benefits!$E:$E,"Revenue",Benefits!$F:$F,"USD",Benefits!$D:$D,"Plan Base",Benefits!$CS:$CS,$A24) -> 0.33 | AO24: =SUMIFS(Benefits!$BK:$BK,Benefits!$E:$E,"Revenue",Benefits!$F:$F,"USD",Benefits!$D:$D,"Plan Base",Benefits!$CS:$CS,$A24) -> 0.33 | AP24: =SUMIFS(Benefits!$BL:$BL,Benefits!$E:$E,"Revenue",Benefits!$F:$F,"USD",Benefits!$D:$D,"Plan Base",Benefits!$CS:$CS,$A24) -> 0.33 | AQ24: =SUMIFS(Benefits!$BM:$BM,Benefits!$E:$E,"Revenue",Benefits!$F:$F,"USD",Benefits!$D:$D,"Plan Base",Benefits!$CS:$CS,$A24) -> 0.33 | AR24: =SUMIFS(Benefits!$BN:$BN,Benefits!$E:$E,"Revenue",Benefits!$F:$F,"USD",Benefits!$D:$D,"Plan Base",Benefits!$CS:$CS,$A24) -> 0.33 | AS24: =SUMIFS(Benefits!$BO:$BO,Benefits!$E:$E,"Revenue",Benefits!$F:$F,"USD",Benefits!$D:$D,"Plan Base",Benefits!$CS:$CS,$A24) -> 0.33 | AT24: =SUMIFS(Benefits!$BP:$BP,Benefits!$E:$E,"Revenue",Benefits!$F:$F,"USD",Benefits!$D:$D,"Plan Base",Benefits!$CS:$CS,$A24) -> 0.33 | AU24: =SUMIFS(Benefits!$BQ:$BQ,Benefits!$E:$E,"Revenue",Benefits!$F:$F,"USD",Benefits!$D:$D,"Plan Base",Benefits!$CS:$CS,$A24) -> 0.33 | AV24: =SUMIFS(Benefits!$BR:$BR,Benefits!$E:$E,"Revenue",Benefits!$F:$F,"USD",Benefits!$D:$D,"Plan Base",Benefits!$CS:$CS,$A24) -> 0.33 | AW24: =SUMIFS(Benefits!$BS:$BS,Benefits!$E:$E,"Revenue",Benefits!$F:$F,"USD",Benefits!$D:$D,"Plan Base",Benefits!$CS:$CS,$A24) -> 0.33 | AX24: =SUMIFS(Benefits!$BT:$BT,Benefits!$E:$E,"Revenue",Benefits!$F:$F,"USD",Benefits!$D:$D,"Plan Base",Benefits!$CS:$CS,$A24) -> 0.33 | AY24: =SUMIFS(Benefits!$BU:$BU,Benefits!$E:$E,"Revenue",Benefits!$F:$F,"USD",Benefits!$D:$D,"Plan Base",Benefits!$CS:$CS,$A24) -> 0.33 | AZ24: =SUMIFS(Benefits!$BV:$BV,Benefits!$E:$E,"Revenue",Benefits!$F:$F,"USD",Benefits!$D:$D,"Plan Base",Benefits!$CS:$CS,$A24) -> 0.33 | BA24: =SUMIFS(Benefits!$BW:$BW,Benefits!$E:$E,"Revenue",Benefits!$F:$F,"USD",Benefits!$D:$D,"Plan Base",Benefits!$CS:$CS,$A24) -> 0.33 | BB24: =SUMIFS(Benefits!$BX:$BX,Benefits!$E:$E,"Revenue",Benefits!$F:$F,"USD",Benefits!$D:$D,"Plan Base",Benefits!$CS:$CS,$A24) -> 0.33 | BC24: =SUMIFS(Benefits!$BY:$BY,Benefits!$E:$E,"Revenue",Benefits!$F:$F,"USD",Benefits!$D:$D,"Plan Base",Benefits!$CS:$CS,$A24) -> 0.33 | BD24: =SUMIFS(Benefits!$BZ:$BZ,Benefits!$E:$E,"Revenue",Benefits!$F:$F,"USD",Benefits!$D:$D,"Plan Base",Benefits!$CS:$CS,$A24) -> 0.33 | BE24: =SUMIFS(Benefits!$CA:$CA,Benefits!$E:$E,"Revenue",Benefits!$F:$F,"USD",Benefits!$D:$D,"Plan Base",Benefits!$CS:$CS,$A24) -> 0.33 | BF24: =SUMIFS(Benefits!$CB:$CB,Benefits!$E:$E,"Revenue",Benefits!$F:$F,"USD",Benefits!$D:$D,"Plan Base",Benefits!$CS:$CS,$A24) -> 0.33 | BG24: =SUMIFS(Benefits!$CC:$CC,Benefits!$E:$E,"Revenue",Benefits!$F:$F,"USD",Benefits!$D:$D,"Plan Base",Benefits!$CS:$CS,$A24) -> 0.33 | BH24: =SUMIFS(Benefits!$CD:$CD,Benefits!$E:$E,"Revenue",Benefits!$F:$F,"USD",Benefits!$D:$D,"Plan Base",Benefits!$CS:$CS,$A24) -> 0.33 | BI24: =SUMIFS(Benefits!$CE:$CE,Benefits!$E:$E,"Revenue",Benefits!$F:$F,"USD",Benefits!$D:$D,"Plan Base",Benefits!$CS:$CS,$A24) -> 0.33
A25: Eastbridge Region | B25: =SUMIFS(Benefits!$S:$S,Benefits!$E:$E,"Revenue",Benefits!$F:$F,"USD",Benefits!$D:$D,"Plan Base",Benefits!$CS:$CS,$A25) -> 0 | C25: =SUMIFS(Benefits!$T:$T,Benefits!$E:$E,"Revenue",Benefits!$F:$F,"USD",Benefits!$D:$D,"Plan Base",Benefits!$CS:$CS,$A25) -> 1.385 | D25: =SUMIFS(Benefits!$U:$U,Benefits!$E:$E,"Revenue",Benefits!$F:$F,"USD",Benefits!$D:$D,"Plan Base",Benefits!$CS:$CS,$A25) -> 3.764 | E25: =SUMIFS(Benefits!$V:$V,Benefits!$E:$E,"Revenue",Benefits!$F:$F,"USD",Benefits!$D:$D,"Plan Base",Benefits!$CS:$CS,$A25) -> 3.764 | F25: =SUMIFS(Benefits!$W:$W,Benefits!$E:$E,"Revenue",Benefits!$F:$F,"USD",Benefits!$D:$D,"Plan Base",Benefits!$CS:$CS,$A25) -> 3.764 | H25: =SUMIFS(Benefits!$AD:$AD,Benefits!$E:$E,"Revenue",Benefits!$F:$F,"USD",Benefits!$D:$D,"Plan Base",Benefits!$CS:$CS,$A25) -> 0 | I25: =SUMIFS(Benefits!$AE:$AE,Benefits!$E:$E,"Revenue",Benefits!$F:$F,"USD",Benefits!$D:$D,"Plan Base",Benefits!$CS:$CS,$A25) -> 0 | J25: =SUMIFS(Benefits!$AF:$AF,Benefits!$E:$E,"Revenue",Benefits!$F:$F,"USD",Benefits!$D:$D,"Plan Base",Benefits!$CS:$CS,$A25) -> 0 | K25: =SUMIFS(Benefits!$AG:$AG,Benefits!$E:$E,"Revenue",Benefits!$F:$F,"USD",Benefits!$D:$D,"Plan Base",Benefits!$CS:$CS,$A25) -> 0 | L25: =SUMIFS(Benefits!$AH:$AH,Benefits!$E:$E,"Revenue",Benefits!$F:$F,"USD",Benefits!$D:$D,"Plan Base",Benefits!$CS:$CS,$A25) -> 0 | M25: =SUMIFS(Benefits!$AI:$AI,Benefits!$E:$E,"Revenue",Benefits!$F:$F,"USD",Benefits!$D:$D,"Plan Base",Benefits!$CS:$CS,$A25) -> 0 | N25: =SUMIFS(Benefits!$AJ:$AJ,Benefits!$E:$E,"Revenue",Benefits!$F:$F,"USD",Benefits!$D:$D,"Plan Base",Benefits!$CS:$CS,$A25) -> 0 | O25: =SUMIFS(Benefits!$AK:$AK,Benefits!$E:$E,"Revenue",Benefits!$F:$F,"USD",Benefits!$D:$D,"Plan Base",Benefits!$CS:$CS,$A25) -> 0 | P25: =SUMIFS(Benefits!$AL:$AL,Benefits!$E:$E,"Revenue",Benefits!$F:$F,"USD",Benefits!$D:$D,"Plan Base",Benefits!$CS:$CS,$A25) -> 0 | Q25: =SUMIFS(Benefits!$AM:$AM,Benefits!$E:$E,"Revenue",Benefits!$F:$F,"USD",Benefits!$D:$D,"Plan Base",Benefits!$CS:$CS,$A25) -> 0 | R25: =SUMIFS(Benefits!$AN:$AN,Benefits!$E:$E,"Revenue",Benefits!$F:$F,"USD",Benefits!$D:$D,"Plan Base",Benefits!$CS:$CS,$A25) -> 0 | S25: =SUMIFS(Benefits!$AO:$AO,Benefits!$E:$E,"Revenue",Benefits!$F:$F,"USD",Benefits!$D:$D,"Plan Base",Benefits!$CS:$CS,$A25) -> 0 | T25: =SUMIFS(Benefits!$AP:$AP,Benefits!$E:$E,"Revenue",Benefits!$F:$F,"USD",Benefits!$D:$D,"Plan Base",Benefits!$CS:$CS,$A25) -> 0.15716667 | U25: =SUMIFS(Benefits!$AQ:$AQ,Benefits!$E:$E,"Revenue",Benefits!$F:$F,"USD",Benefits!$D:$D,"Plan Base",Benefits!$CS:$CS,$A25) -> 0.15716667 | V25: =SUMIFS(Benefits!$AR:$AR,Benefits!$E:$E,"Revenue",Benefits!$F:$F,"USD",Benefits!$D:$D,"Plan Base",Benefits!$CS:$CS,$A25) -> 0.26766667 | W25: =SUMIFS(Benefits!$AS:$AS,Benefits!$E:$E,"Revenue",Benefits!$F:$F,"USD",Benefits!$D:$D,"Plan Base",Benefits!$CS:$CS,$A25) -> 0.26766667 | X25: =SUMIFS(Benefits!$AT:$AT,Benefits!$E:$E,"Revenue",Benefits!$F:$F,"USD",Benefits!$D:$D,"Plan Base",Benefits!$CS:$CS,$A25) -> 0.26766667 | Y25: =SUMIFS(Benefits!$AU:$AU,Benefits!$E:$E,"Revenue",Benefits!$F:$F,"USD",Benefits!$D:$D,"Plan Base",Benefits!$CS:$CS,$A25) -> 0.26766667 | Z25: =SUMIFS(Benefits!$AV:$AV,Benefits!$E:$E,"Revenue",Benefits!$F:$F,"USD",Benefits!$D:$D,"Plan Base",Benefits!$CS:$CS,$A25) -> 0.31366667 | AA25: =SUMIFS(Benefits!$AW:$AW,Benefits!$E:$E,"Revenue",Benefits!$F:$F,"USD",Benefits!$D:$D,"Plan Base",Benefits!$CS:$CS,$A25) -> 0.31366667 | AB25: =SUMIFS(Benefits!$AX:$AX,Benefits!$E:$E,"Revenue",Benefits!$F:$F,"USD",Benefits!$D:$D,"Plan Base",Benefits!$CS:$CS,$A25) -> 0.31366667 | AC25: =SUMIFS(Benefits!$AY:$AY,Benefits!$E:$E,"Revenue",Benefits!$F:$F,"USD",Benefits!$D:$D,"Plan Base",Benefits!$CS:$CS,$A25) -> 0.31366667 | AD25: =SUMIFS(Benefits!$AZ:$AZ,Benefits!$E:$E,"Revenue",Benefits!$F:$F,"USD",Benefits!$D:$D,"Plan Base",Benefits!$CS:$CS,$A25) -> 0.31366667 | AE25: =SUMIFS(Benefits!$BA:$BA,Benefits!$E:$E,"Revenue",Benefits!$F:$F,"USD",Benefits!$D:$D,"Plan Base",Benefits!$CS:$CS,$A25) -> 0.31366667 | AF25: =SUMIFS(Benefits!$BB:$BB,Benefits!$E:$E,"Revenue",Benefits!$F:$F,"USD",Benefits!$D:$D,"Plan Base",Benefits!$CS:$CS,$A25) -> 0.31366667 | AG25: =SUMIFS(Benefits!$BC:$BC,Benefits!$E:$E,"Revenue",Benefits!$F:$F,"USD",Benefits!$D:$D,"Plan Base",Benefits!$CS:$CS,$A25) -> 0.31366667 | AH25: =SUMIFS(Benefits!$BD:$BD,Benefits!$E:$E,"Revenue",Benefits!$F:$F,"USD",Benefits!$D:$D,"Plan Base",Benefits!$CS:$CS,$A25) -> 0.31366667 | AI25: =SUMIFS(Benefits!$BE:$BE,Benefits!$E:$E,"Revenue",Benefits!$F:$F,"USD",Benefits!$D:$D,"Plan Base",Benefits!$CS:$CS,$A25) -> 0.31366667 | AJ25: =SUMIFS(Benefits!$BF:$BF,Benefits!$E:$E,"Revenue",Benefits!$F:$F,"USD",Benefits!$D:$D,"Plan Base",Benefits!$CS:$CS,$A25) -> 0.31366667 | AK25: =SUMIFS(Benefits!$BG:$BG,Benefits!$E:$E,"Revenue",Benefits!$F:$F,"USD",Benefits!$D:$D,"Plan Base",Benefits!$CS:$CS,$A25) -> 0.31366667 | AL25: =SUMIFS(Benefits!$BH:$BH,Benefits!$E:$E,"Revenue",Benefits!$F:$F,"USD",Benefits!$D:$D,"Plan Base",Benefits!$CS:$CS,$A25) -> 0.31366667 | AM25: =SUMIFS(Benefits!$BI:$BI,Benefits!$E:$E,"Revenue",Benefits!$F:$F,"USD",Benefits!$D:$D,"Plan Base",Benefits!$CS:$CS,$A25) -> 0.31366667 | AN25: =SUMIFS(Benefits!$BJ:$BJ,Benefits!$E:$E,"Revenue",Benefits!$F:$F,"USD",Benefits!$D:$D,"Plan Base",Benefits!$CS:$CS,$A25) -> 0.31366667 | AO25: =SUMIFS(Benefits!$BK:$BK,Benefits!$E:$E,"Revenue",Benefits!$F:$F,"USD",Benefits!$D:$D,"Plan Base",Benefits!$CS:$CS,$A25) -> 0.31366667 | AP25: =SUMIFS(Benefits!$BL:$BL,Benefits!$E:$E,"Revenue",Benefits!$F:$F,"USD",Benefits!$D:$D,"Plan Base",Benefits!$CS:$CS,$A25) -> 0.31366667 | AQ25: =SUMIFS(Benefits!$BM:$BM,Benefits!$E:$E,"Revenue",Benefits!$F:$F,"USD",Benefits!$D:$D,"Plan Base",Benefits!$CS:$CS,$A25) -> 0.31366667 | AR25: =SUMIFS(Benefits!$BN:$BN,Benefits!$E:$E,"Revenue",Benefits!$F:$F,"USD",Benefits!$D:$D,"Plan Base",Benefits!$CS:$CS,$A25) -> 0.31366667 | AS25: =SUMIFS(Benefits!$BO:$BO,Benefits!$E:$E,"Revenue",Benefits!$F:$F,"USD",Benefits!$D:$D,"Plan Base",Benefits!$CS:$CS,$A25) -> 0.31366667 | AT25: =SUMIFS(Benefits!$BP:$BP,Benefits!$E:$E,"Revenue",Benefits!$F:$F,"USD",Benefits!$D:$D,"Plan Base",Benefits!$CS:$CS,$A25) -> 0.31366667 | AU25: =SUMIFS(Benefits!$BQ:$BQ,Benefits!$E:$E,"Revenue",Benefits!$F:$F,"USD",Benefits!$D:$D,"Plan Base",Benefits!$CS:$CS,$A25) -> 0.31366667 | AV25: =SUMIFS(Benefits!$BR:$BR,Benefits!$E:$E,"Revenue",Benefits!$F:$F,"USD",Benefits!$D:$D,"Plan Base",Benefits!$CS:$CS,$A25) -> 0.31366667 | AW25: =SUMIFS(Benefits!$BS:$BS,Benefits!$E:$E,"Revenue",Benefits!$F:$F,"USD",Benefits!$D:$D,"Plan Base",Benefits!$CS:$CS,$A25) -> 0.31366667 | AX25: =SUMIFS(Benefits!$BT:$BT,Benefits!$E:$E,"Revenue",Benefits!$F:$F,"USD",Benefits!$D:$D,"Plan Base",Benefits!$CS:$CS,$A25) -> 0.31366667 | AY25: =SUMIFS(Benefits!$BU:$BU,Benefits!$E:$E,"Revenue",Benefits!$F:$F,"USD",Benefits!$D:$D,"Plan Base",Benefits!$CS:$CS,$A25) -> 0.31366667 | AZ25: =SUMIFS(Benefits!$BV:$BV,Benefits!$E:$E,"Revenue",Benefits!$F:$F,"USD",Benefits!$D:$D,"Plan Base",Benefits!$CS:$CS,$A25) -> 0.31366667 | BA25: =SUMIFS(Benefits!$BW:$BW,Benefits!$E:$E,"Revenue",Benefits!$F:$F,"USD",Benefits!$D:$D,"Plan Base",Benefits!$CS:$CS,$A25) -> 0.31366667 | BB25: =SUMIFS(Benefits!$BX:$BX,Benefits!$E:$E,"Revenue",Benefits!$F:$F,"USD",Benefits!$D:$D,"Plan Base",Benefits!$CS:$CS,$A25) -> 0.31366667 | BC25: =SUMIFS(Benefits!$BY:$BY,Benefits!$E:$E,"Revenue",Benefits!$F:$F,"USD",Benefits!$D:$D,"Plan Base",Benefits!$CS:$CS,$A25) -> 0.31366667 | BD25: =SUMIFS(Benefits!$BZ:$BZ,Benefits!$E:$E,"Revenue",Benefits!$F:$F,"USD",Benefits!$D:$D,"Plan Base",Benefits!$CS:$CS,$A25) -> 0.31366667 | BE25: =SUMIFS(Benefits!$CA:$CA,Benefits!$E:$E,"Revenue",Benefits!$F:$F,"USD",Benefits!$D:$D,"Plan Base",Benefits!$CS:$CS,$A25) -> 0.31366667 | BF25: =SUMIFS(Benefits!$CB:$CB,Benefits!$E:$E,"Revenue",Benefits!$F:$F,"USD",Benefits!$D:$D,"Plan Base",Benefits!$CS:$CS,$A25) -> 0.31366667 | BG25: =SUMIFS(Benefits!$CC:$CC,Benefits!$E:$E,"Revenue",Benefits!$F:$F,"USD",Benefits!$D:$D,"Plan Base",Benefits!$CS:$CS,$A25) -> 0.31366667 | BH25: =SUMIFS(Benefits!$CD:$CD,Benefits!$E:$E,"Revenue",Benefits!$F:$F,"USD",Benefits!$D:$D,"Plan Base",Benefits!$CS:$CS,$A25) -> 0.31366667 | BI25: =SUMIFS(Benefits!$CE:$CE,Benefits!$E:$E,"Revenue",Benefits!$F:$F,"USD",Benefits!$D:$D,"Plan Base",Benefits!$CS:$CS,$A25) -> 0.31366667
A26: Northpeak Region | B26: =SUMIFS(Benefits!$S:$S,Benefits!$E:$E,"Revenue",Benefits!$F:$F,"USD",Benefits!$D:$D,"Plan Base",Benefits!$CS:$CS,$A26) -> 0.572 | C26: =SUMIFS(Benefits!$T:$T,Benefits!$E:$E,"Revenue",Benefits!$F:$F,"USD",Benefits!$D:$D,"Plan Base",Benefits!$CS:$CS,$A26) -> 2.366 | D26: =SUMIFS(Benefits!$U:$U,Benefits!$E:$E,"Revenue",Benefits!$F:$F,"USD",Benefits!$D:$D,"Plan Base",Benefits!$CS:$CS,$A26) -> 3.678 | E26: =SUMIFS(Benefits!$V:$V,Benefits!$E:$E,"Revenue",Benefits!$F:$F,"USD",Benefits!$D:$D,"Plan Base",Benefits!$CS:$CS,$A26) -> 3.678 | F26: =SUMIFS(Benefits!$W:$W,Benefits!$E:$E,"Revenue",Benefits!$F:$F,"USD",Benefits!$D:$D,"Plan Base",Benefits!$CS:$CS,$A26) -> 3.678 | H26: =SUMIFS(Benefits!$AD:$AD,Benefits!$E:$E,"Revenue",Benefits!$F:$F,"USD",Benefits!$D:$D,"Plan Base",Benefits!$CS:$CS,$A26) -> 0 | I26: =SUMIFS(Benefits!$AE:$AE,Benefits!$E:$E,"Revenue",Benefits!$F:$F,"USD",Benefits!$D:$D,"Plan Base",Benefits!$CS:$CS,$A26) -> 0 | J26: =SUMIFS(Benefits!$AF:$AF,Benefits!$E:$E,"Revenue",Benefits!$F:$F,"USD",Benefits!$D:$D,"Plan Base",Benefits!$CS:$CS,$A26) -> 0 | K26: =SUMIFS(Benefits!$AG:$AG,Benefits!$E:$E,"Revenue",Benefits!$F:$F,"USD",Benefits!$D:$D,"Plan Base",Benefits!$CS:$CS,$A26) -> 0 | L26: =SUMIFS(Benefits!$AH:$AH,Benefits!$E:$E,"Revenue",Benefits!$F:$F,"USD",Benefits!$D:$D,"Plan Base",Benefits!$CS:$CS,$A26) -> 0 | M26: =SUMIFS(Benefits!$AI:$AI,Benefits!$E:$E,"Revenue",Benefits!$F:$F,"USD",Benefits!$D:$D,"Plan Base",Benefits!$CS:$CS,$A26) -> 0.572 | N26: =SUMIFS(Benefits!$AJ:$AJ,Benefits!$E:$E,"Revenue",Benefits!$F:$F,"USD",Benefits!$D:$D,"Plan Base",Benefits!$CS:$CS,$A26) -> 0.10083333 | O26: =SUMIFS(Benefits!$AK:$AK,Benefits!$E:$E,"Revenue",Benefits!$F:$F,"USD",Benefits!$D:$D,"Plan Base",Benefits!$CS:$CS,$A26) -> 0.10083333 | P26: =SUMIFS(Benefits!$AL:$AL,Benefits!$E:$E,"Revenue",Benefits!$F:$F,"USD",Benefits!$D:$D,"Plan Base",Benefits!$CS:$CS,$A26) -> 0.10083333 | Q26: =SUMIFS(Benefits!$AM:$AM,Benefits!$E:$E,"Revenue",Benefits!$F:$F,"USD",Benefits!$D:$D,"Plan Base",Benefits!$CS:$CS,$A26) -> 0.10083333 | R26: =SUMIFS(Benefits!$AN:$AN,Benefits!$E:$E,"Revenue",Benefits!$F:$F,"USD",Benefits!$D:$D,"Plan Base",Benefits!$CS:$CS,$A26) -> 0.10083333 | S26: =SUMIFS(Benefits!$AO:$AO,Benefits!$E:$E,"Revenue",Benefits!$F:$F,"USD",Benefits!$D:$D,"Plan Base",Benefits!$CS:$CS,$A26) -> 0.10083333 | T26: =SUMIFS(Benefits!$AP:$AP,Benefits!$E:$E,"Revenue",Benefits!$F:$F,"USD",Benefits!$D:$D,"Plan Base",Benefits!$CS:$CS,$A26) -> 0.10083333 | U26: =SUMIFS(Benefits!$AQ:$AQ,Benefits!$E:$E,"Revenue",Benefits!$F:$F,"USD",Benefits!$D:$D,"Plan Base",Benefits!$CS:$CS,$A26) -> 0.20083333 | V26: =SUMIFS(Benefits!$AR:$AR,Benefits!$E:$E,"Revenue",Benefits!$F:$F,"USD",Benefits!$D:$D,"Plan Base",Benefits!$CS:$CS,$A26) -> 0.20083333 | W26: =SUMIFS(Benefits!$AS:$AS,Benefits!$E:$E,"Revenue",Benefits!$F:$F,"USD",Benefits!$D:$D,"Plan Base",Benefits!$CS:$CS,$A26) -> 0.4195 | X26: =SUMIFS(Benefits!$AT:$AT,Benefits!$E:$E,"Revenue",Benefits!$F:$F,"USD",Benefits!$D:$D,"Plan Base",Benefits!$CS:$CS,$A26) -> 0.4195 | Y26: =SUMIFS(Benefits!$AU:$AU,Benefits!$E:$E,"Revenue",Benefits!$F:$F,"USD",Benefits!$D:$D,"Plan Base",Benefits!$CS:$CS,$A26) -> 0.4195 | Z26: =SUMIFS(Benefits!$AV:$AV,Benefits!$E:$E,"Revenue",Benefits!$F:$F,"USD",Benefits!$D:$D,"Plan Base",Benefits!$CS:$CS,$A26) -> 0.3065 | AA26: =SUMIFS(Benefits!$AW:$AW,Benefits!$E:$E,"Revenue",Benefits!$F:$F,"USD",Benefits!$D:$D,"Plan Base",Benefits!$CS:$CS,$A26) -> 0.3065 | AB26: =SUMIFS(Benefits!$AX:$AX,Benefits!$E:$E,"Revenue",Benefits!$F:$F,"USD",Benefits!$D:$D,"Plan Base",Benefits!$CS:$CS,$A26) -> 0.3065 | AC26: =SUMIFS(Benefits!$AY:$AY,Benefits!$E:$E,"Revenue",Benefits!$F:$F,"USD",Benefits!$D:$D,"Plan Base",Benefits!$CS:$CS,$A26) -> 0.3065 | AD26: =SUMIFS(Benefits!$AZ:$AZ,Benefits!$E:$E,"Revenue",Benefits!$F:$F,"USD",Benefits!$D:$D,"Plan Base",Benefits!$CS:$CS,$A26) -> 0.3065 | AE26: =SUMIFS(Benefits!$BA:$BA,Benefits!$E:$E,"Revenue",Benefits!$F:$F,"USD",Benefits!$D:$D,"Plan Base",Benefits!$CS:$CS,$A26) -> 0.3065 | AF26: =SUMIFS(Benefits!$BB:$BB,Benefits!$E:$E,"Revenue",Benefits!$F:$F,"USD",Benefits!$D:$D,"Plan Base",Benefits!$CS:$CS,$A26) -> 0.3065 | AG26: =SUMIFS(Benefits!$BC:$BC,Benefits!$E:$E,"Revenue",Benefits!$F:$F,"USD",Benefits!$D:$D,"Plan Base",Benefits!$CS:$CS,$A26) -> 0.3065 | AH26: =SUMIFS(Benefits!$BD:$BD,Benefits!$E:$E,"Revenue",Benefits!$F:$F,"USD",Benefits!$D:$D,"Plan Base",Benefits!$CS:$CS,$A26) -> 0.3065 | AI26: =SUMIFS(Benefits!$BE:$BE,Benefits!$E:$E,"Revenue",Benefits!$F:$F,"USD",Benefits!$D:$D,"Plan Base",Benefits!$CS:$CS,$A26) -> 0.3065 | AJ26: =SUMIFS(Benefits!$BF:$BF,Benefits!$E:$E,"Revenue",Benefits!$F:$F,"USD",Benefits!$D:$D,"Plan Base",Benefits!$CS:$CS,$A26) -> 0.3065 | AK26: =SUMIFS(Benefits!$BG:$BG,Benefits!$E:$E,"Revenue",Benefits!$F:$F,"USD",Benefits!$D:$D,"Plan Base",Benefits!$CS:$CS,$A26) -> 0.3065 | AL26: =SUMIFS(Benefits!$BH:$BH,Benefits!$E:$E,"Revenue",Benefits!$F:$F,"USD",Benefits!$D:$D,"Plan Base",Benefits!$CS:$CS,$A26) -> 0.3065 | AM26: =SUMIFS(Benefits!$BI:$BI,Benefits!$E:$E,"Revenue",Benefits!$F:$F,"USD",Benefits!$D:$D,"Plan Base",Benefits!$CS:$CS,$A26) -> 0.3065 | AN26: =SUMIFS(Benefits!$BJ:$BJ,Benefits!$E:$E,"Revenue",Benefits!$F:$F,"USD",Benefits!$D:$D,"Plan Base",Benefits!$CS:$CS,$A26) -> 0.3065 | AO26: =SUMIFS(Benefits!$BK:$BK,Benefits!$E:$E,"Revenue",Benefits!$F:$F,"USD",Benefits!$D:$D,"Plan Base",Benefits!$CS:$CS,$A26) -> 0.3065 | AP26: =SUMIFS(Benefits!$BL:$BL,Benefits!$E:$E,"Revenue",Benefits!$F:$F,"USD",Benefits!$D:$D,"Plan Base",Benefits!$CS:$CS,$A26) -> 0.3065 | AQ26: =SUMIFS(Benefits!$BM:$BM,Benefits!$E:$E,"Revenue",Benefits!$F:$F,"USD",Benefits!$D:$D,"Plan Base",Benefits!$CS:$CS,$A26) -> 0.3065 | AR26: =SUMIFS(Benefits!$BN:$BN,Benefits!$E:$E,"Revenue",Benefits!$F:$F,"USD",Benefits!$D:$D,"Plan Base",Benefits!$CS:$CS,$A26) -> 0.3065 | AS26: =SUMIFS(Benefits!$BO:$BO,Benefits!$E:$E,"Revenue",Benefits!$F:$F,"USD",Benefits!$D:$D,"Plan Base",Benefits!$CS:$CS,$A26) -> 0.3065 | AT26: =SUMIFS(Benefits!$BP:$BP,Benefits!$E:$E,"Revenue",Benefits!$F:$F,"USD",Benefits!$D:$D,"Plan Base",Benefits!$CS:$CS,$A26) -> 0.3065 | AU26: =SUMIFS(Benefits!$BQ:$BQ,Benefits!$E:$E,"Revenue",Benefits!$F:$F,"USD",Benefits!$D:$D,"Plan Base",Benefits!$CS:$CS,$A26) -> 0.3065 | AV26: =SUMIFS(Benefits!$BR:$BR,Benefits!$E:$E,"Revenue",Benefits!$F:$F,"USD",Benefits!$D:$D,"Plan Base",Benefits!$CS:$CS,$A26) -> 0.3065 | AW26: =SUMIFS(Benefits!$BS:$BS,Benefits!$E:$E,"Revenue",Benefits!$F:$F,"USD",Benefits!$D:$D,"Plan Base",Benefits!$CS:$CS,$A26) -> 0.3065 | AX26: =SUMIFS(Benefits!$BT:$BT,Benefits!$E:$E,"Revenue",Benefits!$F:$F,"USD",Benefits!$D:$D,"Plan Base",Benefits!$CS:$CS,$A26) -> 0.3065 | AY26: =SUMIFS(Benefits!$BU:$BU,Benefits!$E:$E,"Revenue",Benefits!$F:$F,"USD",Benefits!$D:$D,"Plan Base",Benefits!$CS:$CS,$A26) -> 0.3065 | AZ26: =SUMIFS(Benefits!$BV:$BV,Benefits!$E:$E,"Revenue",Benefits!$F:$F,"USD",Benefits!$D:$D,"Plan Base",Benefits!$CS:$CS,$A26) -> 0.3065 | BA26: =SUMIFS(Benefits!$BW:$BW,Benefits!$E:$E,"Revenue",Benefits!$F:$F,"USD",Benefits!$D:$D,"Plan Base",Benefits!$CS:$CS,$A26) -> 0.3065 | BB26: =SUMIFS(Benefits!$BX:$BX,Benefits!$E:$E,"Revenue",Benefits!$F:$F,"USD",Benefits!$D:$D,"Plan Base",Benefits!$CS:$CS,$A26) -> 0.3065 | BC26: =SUMIFS(Benefits!$BY:$BY,Benefits!$E:$E,"Revenue",Benefits!$F:$F,"USD",Benefits!$D:$D,"Plan Base",Benefits!$CS:$CS,$A26) -> 0.3065 | BD26: =SUMIFS(Benefits!$BZ:$BZ,Benefits!$E:$E,"Revenue",Benefits!$F:$F,"USD",Benefits!$D:$D,"Plan Base",Benefits!$CS:$CS,$A26) -> 0.3065 | BE26: =SUMIFS(Benefits!$CA:$CA,Benefits!$E:$E,"Revenue",Benefits!$F:$F,"USD",Benefits!$D:$D,"Plan Base",Benefits!$CS:$CS,$A26) -> 0.3065 | BF26: =SUMIFS(Benefits!$CB:$CB,Benefits!$E:$E,"Revenue",Benefits!$F:$F,"USD",Benefits!$D:$D,"Plan Base",Benefits!$CS:$CS,$A26) -> 0.3065 | BG26: =SUMIFS(Benefits!$CC:$CC,Benefits!$E:$E,"Revenue",Benefits!$F:$F,"USD",Benefits!$D:$D,"Plan Base",Benefits!$CS:$CS,$A26) -> 0.3065 | BH26: =SUMIFS(Benefits!$CD:$CD,Benefits!$E:$E,"Revenue",Benefits!$F:$F,"USD",Benefits!$D:$D,"Plan Base",Benefits!$CS:$CS,$A26) -> 0.3065 | BI26: =SUMIFS(Benefits!$CE:$CE,Benefits!$E:$E,"Revenue",Benefits!$F:$F,"USD",Benefits!$D:$D,"Plan Base",Benefits!$CS:$CS,$A26) -> 0.3065
A27: Southgate Region | B27: =SUMIFS(Benefits!$S:$S,Benefits!$E:$E,"Revenue",Benefits!$F:$F,"USD",Benefits!$D:$D,"Plan Base",Benefits!$CS:$CS,$A27) -> 0.598 | C27: =SUMIFS(Benefits!$T:$T,Benefits!$E:$E,"Revenue",Benefits!$F:$F,"USD",Benefits!$D:$D,"Plan Base",Benefits!$CS:$CS,$A27) -> 2.044 | D27: =SUMIFS(Benefits!$U:$U,Benefits!$E:$E,"Revenue",Benefits!$F:$F,"USD",Benefits!$D:$D,"Plan Base",Benefits!$CS:$CS,$A27) -> 3.602 | E27: =SUMIFS(Benefits!$V:$V,Benefits!$E:$E,"Revenue",Benefits!$F:$F,"USD",Benefits!$D:$D,"Plan Base",Benefits!$CS:$CS,$A27) -> 3.602 | F27: =SUMIFS(Benefits!$W:$W,Benefits!$E:$E,"Revenue",Benefits!$F:$F,"USD",Benefits!$D:$D,"Plan Base",Benefits!$CS:$CS,$A27) -> 3.602 | H27: =SUMIFS(Benefits!$AD:$AD,Benefits!$E:$E,"Revenue",Benefits!$F:$F,"USD",Benefits!$D:$D,"Plan Base",Benefits!$CS:$CS,$A27) -> 0 | I27: =SUMIFS(Benefits!$AE:$AE,Benefits!$E:$E,"Revenue",Benefits!$F:$F,"USD",Benefits!$D:$D,"Plan Base",Benefits!$CS:$CS,$A27) -> 0 | J27: =SUMIFS(Benefits!$AF:$AF,Benefits!$E:$E,"Revenue",Benefits!$F:$F,"USD",Benefits!$D:$D,"Plan Base",Benefits!$CS:$CS,$A27) -> 0 | K27: =SUMIFS(Benefits!$AG:$AG,Benefits!$E:$E,"Revenue",Benefits!$F:$F,"USD",Benefits!$D:$D,"Plan Base",Benefits!$CS:$CS,$A27) -> 0 | L27: =SUMIFS(Benefits!$AH:$AH,Benefits!$E:$E,"Revenue",Benefits!$F:$F,"USD",Benefits!$D:$D,"Plan Base",Benefits!$CS:$CS,$A27) -> 0.299 | M27: =SUMIFS(Benefits!$AI:$AI,Benefits!$E:$E,"Revenue",Benefits!$F:$F,"USD",Benefits!$D:$D,"Plan Base",Benefits!$CS:$CS,$A27) -> 0.299 | N27: =SUMIFS(Benefits!$AJ:$AJ,Benefits!$E:$E,"Revenue",Benefits!$F:$F,"USD",Benefits!$D:$D,"Plan Base",Benefits!$CS:$CS,$A27) -> 0.10541667 | O27: =SUMIFS(Benefits!$AK:$AK,Benefits!$E:$E,"Revenue",Benefits!$F:$F,"USD",Benefits!$D:$D,"Plan Base",Benefits!$CS:$CS,$A27) -> 0.17623485 | P27: =SUMIFS(Benefits!$AL:$AL,Benefits!$E:$E,"Revenue",Benefits!$F:$F,"USD",Benefits!$D:$D,"Plan Base",Benefits!$CS:$CS,$A27) -> 0.17623485 | Q27: =SUMIFS(Benefits!$AM:$AM,Benefits!$E:$E,"Revenue",Benefits!$F:$F,"USD",Benefits!$D:$D,"Plan Base",Benefits!$CS:$CS,$A27) -> 0.17623485 | R27: =SUMIFS(Benefits!$AN:$AN,Benefits!$E:$E,"Revenue",Benefits!$F:$F,"USD",Benefits!$D:$D,"Plan Base",Benefits!$CS:$CS,$A27) -> 0.17623485 | S27: =SUMIFS(Benefits!$AO:$AO,Benefits!$E:$E,"Revenue",Benefits!$F:$F,"USD",Benefits!$D:$D,"Plan Base",Benefits!$CS:$CS,$A27) -> 0.17623485 | T27: =SUMIFS(Benefits!$AP:$AP,Benefits!$E:$E,"Revenue",Benefits!$F:$F,"USD",Benefits!$D:$D,"Plan Base",Benefits!$CS:$CS,$A27) -> 0.17623485 | U27: =SUMIFS(Benefits!$AQ:$AQ,Benefits!$E:$E,"Revenue",Benefits!$F:$F,"USD",Benefits!$D:$D,"Plan Base",Benefits!$CS:$CS,$A27) -> 0.17623485 | V27: =SUMIFS(Benefits!$AR:$AR,Benefits!$E:$E,"Revenue",Benefits!$F:$F,"USD",Benefits!$D:$D,"Plan Base",Benefits!$CS:$CS,$A27) -> 0.17623485 | W27: =SUMIFS(Benefits!$AS:$AS,Benefits!$E:$E,"Revenue",Benefits!$F:$F,"USD",Benefits!$D:$D,"Plan Base",Benefits!$CS:$CS,$A27) -> 0.17623485 | X27: =SUMIFS(Benefits!$AT:$AT,Benefits!$E:$E,"Revenue",Benefits!$F:$F,"USD",Benefits!$D:$D,"Plan Base",Benefits!$CS:$CS,$A27) -> 0.17623485 | Y27: =SUMIFS(Benefits!$AU:$AU,Benefits!$E:$E,"Revenue",Benefits!$F:$F,"USD",Benefits!$D:$D,"Plan Base",Benefits!$CS:$CS,$A27) -> 0.17623485 | Z27: =SUMIFS(Benefits!$AV:$AV,Benefits!$E:$E,"Revenue",Benefits!$F:$F,"USD",Benefits!$D:$D,"Plan Base",Benefits!$CS:$CS,$A27) -> 0.30016667 | AA27: =SUMIFS(Benefits!$AW:$AW,Benefits!$E:$E,"Revenue",Benefits!$F:$F,"USD",Benefits!$D:$D,"Plan Base",Benefits!$CS:$CS,$A27) -> 0.30016667 | AB27: =SUMIFS(Benefits!$AX:$AX,Benefits!$E:$E,"Revenue",Benefits!$F:$F,"USD",Benefits!$D:$D,"Plan Base",Benefits!$CS:$CS,$A27) -> 0.30016667 | AC27: =SUMIFS(Benefits!$AY:$AY,Benefits!$E:$E,"Revenue",Benefits!$F:$F,"USD",Benefits!$D:$D,"Plan Base",Benefits!$CS:$CS,$A27) -> 0.30016667 | AD27: =SUMIFS(Benefits!$AZ:$AZ,Benefits!$E:$E,"Revenue",Benefits!$F:$F,"USD",Benefits!$D:$D,"Plan Base",Benefits!$CS:$CS,$A27) -> 0.30016667 | AE27: =SUMIFS(Benefits!$BA:$BA,Benefits!$E:$E,"Revenue",Benefits!$F:$F,"USD",Benefits!$D:$D,"Plan Base",Benefits!$CS:$CS,$A27) -> 0.30016667 | AF27: =SUMIFS(Benefits!$BB:$BB,Benefits!$E:$E,"Revenue",Benefits!$F:$F,"USD",Benefits!$D:$D,"Plan Base",Benefits!$CS:$CS,$A27) -> 0.30016667 | AG27: =SUMIFS(Benefits!$BC:$BC,Benefits!$E:$E,"Revenue",Benefits!$F:$F,"USD",Benefits!$D:$D,"Plan Base",Benefits!$CS:$CS,$A27) -> 0.30016667 | AH27: =SUMIFS(Benefits!$BD:$BD,Benefits!$E:$E,"Revenue",Benefits!$F:$F,"USD",Benefits!$D:$D,"Plan Base",Benefits!$CS:$CS,$A27) -> 0.30016667 | AI27: =SUMIFS(Benefits!$BE:$BE,Benefits!$E:$E,"Revenue",Benefits!$F:$F,"USD",Benefits!$D:$D,"Plan Base",Benefits!$CS:$CS,$A27) -> 0.30016667 | AJ27: =SUMIFS(Benefits!$BF:$BF,Benefits!$E:$E,"Revenue",Benefits!$F:$F,"USD",Benefits!$D:$D,"Plan Base",Benefits!$CS:$CS,$A27) -> 0.30016667 | AK27: =SUMIFS(Benefits!$BG:$BG,Benefits!$E:$E,"Revenue",Benefits!$F:$F,"USD",Benefits!$D:$D,"Plan Base",Benefits!$CS:$CS,$A27) -> 0.30016667 | AL27: =SUMIFS(Benefits!$BH:$BH,Benefits!$E:$E,"Revenue",Benefits!$F:$F,"USD",Benefits!$D:$D,"Plan Base",Benefits!$CS:$CS,$A27) -> 0.30016667 | AM27: =SUMIFS(Benefits!$BI:$BI,Benefits!$E:$E,"Revenue",Benefits!$F:$F,"USD",Benefits!$D:$D,"Plan Base",Benefits!$CS:$CS,$A27) -> 0.30016667 | AN27: =SUMIFS(Benefits!$BJ:$BJ,Benefits!$E:$E,"Revenue",Benefits!$F:$F,"USD",Benefits!$D:$D,"Plan Base",Benefits!$CS:$CS,$A27) -> 0.30016667 | AO27: =SUMIFS(Benefits!$BK:$BK,Benefits!$E:$E,"Revenue",Benefits!$F:$F,"USD",Benefits!$D:$D,"Plan Base",Benefits!$CS:$CS,$A27) -> 0.30016667 | AP27: =SUMIFS(Benefits!$BL:$BL,Benefits!$E:$E,"Revenue",Benefits!$F:$F,"USD",Benefits!$D:$D,"Plan Base",Benefits!$CS:$CS,$A27) -> 0.30016667 | AQ27: =SUMIFS(Benefits!$BM:$BM,Benefits!$E:$E,"Revenue",Benefits!$F:$F,"USD",Benefits!$D:$D,"Plan Base",Benefits!$CS:$CS,$A27) -> 0.30016667 | AR27: =SUMIFS(Benefits!$BN:$BN,Benefits!$E:$E,"Revenue",Benefits!$F:$F,"USD",Benefits!$D:$D,"Plan Base",Benefits!$CS:$CS,$A27) -> 0.30016667 | AS27: =SUMIFS(Benefits!$BO:$BO,Benefits!$E:$E,"Revenue",Benefits!$F:$F,"USD",Benefits!$D:$D,"Plan Base",Benefits!$CS:$CS,$A27) -> 0.30016667 | AT27: =SUMIFS(Benefits!$BP:$BP,Benefits!$E:$E,"Revenue",Benefits!$F:$F,"USD",Benefits!$D:$D,"Plan Base",Benefits!$CS:$CS,$A27) -> 0.30016667 | AU27: =SUMIFS(Benefits!$BQ:$BQ,Benefits!$E:$E,"Revenue",Benefits!$F:$F,"USD",Benefits!$D:$D,"Plan Base",Benefits!$CS:$CS,$A27) -> 0.30016667 | AV27: =SUMIFS(Benefits!$BR:$BR,Benefits!$E:$E,"Revenue",Benefits!$F:$F,"USD",Benefits!$D:$D,"Plan Base",Benefits!$CS:$CS,$A27) -> 0.30016667 | AW27: =SUMIFS(Benefits!$BS:$BS,Benefits!$E:$E,"Revenue",Benefits!$F:$F,"USD",Benefits!$D:$D,"Plan Base",Benefits!$CS:$CS,$A27) -> 0.30016667 | AX27: =SUMIFS(Benefits!$BT:$BT,Benefits!$E:$E,"Revenue",Benefits!$F:$F,"USD",Benefits!$D:$D,"Plan Base",Benefits!$CS:$CS,$A27) -> 0.30016667 | AY27: =SUMIFS(Benefits!$BU:$BU,Benefits!$E:$E,"Revenue",Benefits!$F:$F,"USD",Benefits!$D:$D,"Plan Base",Benefits!$CS:$CS,$A27) -> 0.30016667 | AZ27: =SUMIFS(Benefits!$BV:$BV,Benefits!$E:$E,"Revenue",Benefits!$F:$F,"USD",Benefits!$D:$D,"Plan Base",Benefits!$CS:$CS,$A27) -> 0.30016667 | BA27: =SUMIFS(Benefits!$BW:$BW,Benefits!$E:$E,"Revenue",Benefits!$F:$F,"USD",Benefits!$D:$D,"Plan Base",Benefits!$CS:$CS,$A27) -> 0.30016667 | BB27: =SUMIFS(Benefits!$BX:$BX,Benefits!$E:$E,"Revenue",Benefits!$F:$F,"USD",Benefits!$D:$D,"Plan Base",Benefits!$CS:$CS,$A27) -> 0.30016667 | BC27: =SUMIFS(Benefits!$BY:$BY,Benefits!$E:$E,"Revenue",Benefits!$F:$F,"USD",Benefits!$D:$D,"Plan Base",Benefits!$CS:$CS,$A27) -> 0.30016667 | BD27: =SUMIFS(Benefits!$BZ:$BZ,Benefits!$E:$E,"Revenue",Benefits!$F:$F,"USD",Benefits!$D:$D,"Plan Base",Benefits!$CS:$CS,$A27) -> 0.30016667 | BE27: =SUMIFS(Benefits!$CA:$CA,Benefits!$E:$E,"Revenue",Benefits!$F:$F,"USD",Benefits!$D:$D,"Plan Base",Benefits!$CS:$CS,$A27) -> 0.30016667 | BF27: =SUMIFS(Benefits!$CB:$CB,Benefits!$E:$E,"Revenue",Benefits!$F:$F,"USD",Benefits!$D:$D,"Plan Base",Benefits!$CS:$CS,$A27) -> 0.30016667 | BG27: =SUMIFS(Benefits!$CC:$CC,Benefits!$E:$E,"Revenue",Benefits!$F:$F,"USD",Benefits!$D:$D,"Plan Base",Benefits!$CS:$CS,$A27) -> 0.30016667 | BH27: =SUMIFS(Benefits!$CD:$CD,Benefits!$E:$E,"Revenue",Benefits!$F:$F,"USD",Benefits!$D:$D,"Plan Base",Benefits!$CS:$CS,$A27) -> 0.30016667 | BI27: =SUMIFS(Benefits!$CE:$CE,Benefits!$E:$E,"Revenue",Benefits!$F:$F,"USD",Benefits!$D:$D,"Plan Base",Benefits!$CS:$CS,$A27) -> 0.30016667
A28: Total Revenue | B28: =SUM(B24:B27) -> 1.69 | C28: =SUM(C24:C27) -> 8.115 | D28: =SUM(D24:D27) -> 15.004 | E28: =SUM(E24:E27) -> 15.004 | F28: =SUM(F24:F27) -> 15.004 | H28: =SUM(H24:H27) -> 0 | I28: =SUM(I24:I27) -> 0 | J28: =SUM(J24:J27) -> 0 | K28: =SUM(K24:K27) -> 0 | L28: =SUM(L24:L27) -> 0.299 | M28: =SUM(M24:M27) -> 1.391 | N28: =SUM(N24:N27) -> 0.29791667 | O28: =SUM(O24:O27) -> 0.36873485 | ... BI28: =SUM(BI24:BI27) -> 1.2503333
A29: Gross Margin (USD m)
A30: Westmark Region | B30: =SUMIFS(Benefits!$S:$S,Benefits!$E:$E,"Gross Margin",Benefits!$F:$F,"USD",Benefits!$D:$D,"Plan Base",Benefits!$CS:$CS,$A30) -> 1.52 | C30: =SUMIFS(Benefits!$T:$T,Benefits!$E:$E,"Gross Margin",Benefits!$F:$F,"USD",Benefits!$D:$D,"Plan Base",Benefits!$CS:$CS,$A30) -> 4.34 | D30: =SUMIFS(Benefits!$U:$U,Benefits!$E:$E,"Gross Margin",Benefits!$F:$F,"USD",Benefits!$D:$D,"Plan Base",Benefits!$CS:$CS,$A30) -> 5.78 | E30: =SUMIFS(Benefits!$V:$V,Benefits!$E:$E,"Gross Margin",Benefits!$F:$F,"USD",Benefits!$D:$D,"Plan Base",Benefits!$CS:$CS,$A30) -> 5.78 | F30: =SUMIFS(Benefits!$W:$W,Benefits!$E:$E,"Gross Margin",Benefits!$F:$F,"USD",Benefits!$D:$D,"Plan Base",Benefits!$CS:$CS,$A30) -> 5.78 | H30: =SUMIFS(Benefits!$AD:$AD,Benefits!$E:$E,"Gross Margin",Benefits!$F:$F,"USD",Benefits!$D:$D,"Plan Base",Benefits!$CS:$CS,$A30) -> 0 | I30: =SUMIFS(Benefits!$AE:$AE,Benefits!$E:$E,"Gross Margin",Benefits!$F:$F,"USD",Benefits!$D:$D,"Plan Base",Benefits!$CS:$CS,$A30) -> 0 | J30: =SUMIFS(Benefits!$AF:$AF,Benefits!$E:$E,"Gross Margin",Benefits!$F:$F,"USD",Benefits!$D:$D,"Plan Base",Benefits!$CS:$CS,$A30) -> 0 | K30: =SUMIFS(Benefits!$AG:$AG,Benefits!$E:$E,"Gross Margin",Benefits!$F:$F,"USD",Benefits!$D:$D,"Plan Base",Benefits!$CS:$CS,$A30) -> 0 | L30: =SUMIFS(Benefits!$AH:$AH,Benefits!$E:$E,"Gross Margin",Benefits!$F:$F,"USD",Benefits!$D:$D,"Plan Base",Benefits!$CS:$CS,$A30) -> 0.62 | M30: =SUMIFS(Benefits!$AI:$AI,Benefits!$E:$E,"Gross Margin",Benefits!$F:$F,"USD",Benefits!$D:$D,"Plan Base",Benefits!$CS:$CS,$A30) -> 0.9 | N30: =SUMIFS(Benefits!$AJ:$AJ,Benefits!$E:$E,"Gross Margin",Benefits!$F:$F,"USD",Benefits!$D:$D,"Plan Base",Benefits!$CS:$CS,$A30) -> 0.215 | O30: =SUMIFS(Benefits!$AK:$AK,Benefits!$E:$E,"Gross Margin",Benefits!$F:$F,"USD",Benefits!$D:$D,"Plan Base",Benefits!$CS:$CS,$A30) -> 0.215 | P30: =SUMIFS(Benefits!$AL:$AL,Benefits!$E:$E,"Gross Margin",Benefits!$F:$F,"USD",Benefits!$D:$D,"Plan Base",Benefits!$CS:$CS,$A30) -> 0.277 | Q30: =SUMIFS(Benefits!$AM:$AM,Benefits!$E:$E,"Gross Margin",Benefits!$F:$F,"USD",Benefits!$D:$D,"Plan Base",Benefits!$CS:$CS,$A30) -> 0.30366667 | R30: =SUMIFS(Benefits!$AN:$AN,Benefits!$E:$E,"Gross Margin",Benefits!$F:$F,"USD",Benefits!$D:$D,"Plan Base",Benefits!$CS:$CS,$A30) -> 0.30366667 | S30: =SUMIFS(Benefits!$AO:$AO,Benefits!$E:$E,"Gross Margin",Benefits!$F:$F,"USD",Benefits!$D:$D,"Plan Base",Benefits!$CS:$CS,$A30) -> 0.30366667 | T30: =SUMIFS(Benefits!$AP:$AP,Benefits!$E:$E,"Gross Margin",Benefits!$F:$F,"USD",Benefits!$D:$D,"Plan Base",Benefits!$CS:$CS,$A30) -> 0.30366667 | U30: =SUMIFS(Benefits!$AQ:$AQ,Benefits!$E:$E,"Gross Margin",Benefits!$F:$F,"USD",Benefits!$D:$D,"Plan Base",Benefits!$CS:$CS,$A30) -> 0.30366667 | V30: =SUMIFS(Benefits!$AR:$AR,Benefits!$E:$E,"Gross Margin",Benefits!$F:$F,"USD",Benefits!$D:$D,"Plan Base",Benefits!$CS:$CS,$A30) -> 0.40866667 | W30: =SUMIFS(Benefits!$AS:$AS,Benefits!$E:$E,"Gross Margin",Benefits!$F:$F,"USD",Benefits!$D:$D,"Plan Base",Benefits!$CS:$CS,$A30) -> 0.40866667 | X30: =SUMIFS(Benefits!$AT:$AT,Benefits!$E:$E,"Gross Margin",Benefits!$F:$F,"USD",Benefits!$D:$D,"Plan Base",Benefits!$CS:$CS,$A30) -> 0.40866667 | Y30: =SUMIFS(Benefits!$AU:$AU,Benefits!$E:$E,"Gross Margin",Benefits!$F:$F,"USD",Benefits!$D:$D,"Plan Base",Benefits!$CS:$CS,$A30) -> 0.88866667 | Z30: =SUMIFS(Benefits!$AV:$AV,Benefits!$E:$E,"Gross Margin",Benefits!$F:$F,"USD",Benefits!$D:$D,"Plan Base",Benefits!$CS:$CS,$A30) -> 0.48166667 | AA30: =SUMIFS(Benefits!$AW:$AW,Benefits!$E:$E,"Gross Margin",Benefits!$F:$F,"USD",Benefits!$D:$D,"Plan Base",Benefits!$CS:$CS,$A30) -> 0.48166667 | AB30: =SUMIFS(Benefits!$AX:$AX,Benefits!$E:$E,"Gross Margin",Benefits!$F:$F,"USD",Benefits!$D:$D,"Plan Base",Benefits!$CS:$CS,$A30) -> 0.48166667 | AC30: =SUMIFS(Benefits!$AY:$AY,Benefits!$E:$E,"Gross Margin",Benefits!$F:$F,"USD",Benefits!$D:$D,"Plan Base",Benefits!$CS:$CS,$A30) -> 0.48166667 | AD30: =SUMIFS(Benefits!$AZ:$AZ,Benefits!$E:$E,"Gross Margin",Benefits!$F:$F,"USD",Benefits!$D:$D,"Plan Base",Benefits!$CS:$CS,$A30) -> 0.48166667 | AE30: =SUMIFS(Benefits!$BA:$BA,Benefits!$E:$E,"Gross Margin",Benefits!$F:$F,"USD",Benefits!$D:$D,"Plan Base",Benefits!$CS:$CS,$A30) -> 0.48166667 | AF30: =SUMIFS(Benefits!$BB:$BB,Benefits!$E:$E,"Gross Margin",Benefits!$F:$F,"USD",Benefits!$D:$D,"Plan Base",Benefits!$CS:$CS,$A30) -> 0.48166667 | AG30: =SUMIFS(Benefits!$BC:$BC,Benefits!$E:$E,"Gross Margin",Benefits!$F:$F,"USD",Benefits!$D:$D,"Plan Base",Benefits!$CS:$CS,$A30) -> 0.48166667 | AH30: =SUMIFS(Benefits!$BD:$BD,Benefits!$E:$E,"Gross Margin",Benefits!$F:$F,"USD",Benefits!$D:$D,"Plan Base",Benefits!$CS:$CS,$A30) -> 0.48166667 | AI30: =SUMIFS(Benefits!$BE:$BE,Benefits!$E:$E,"Gross Margin",Benefits!$F:$F,"USD",Benefits!$D:$D,"Plan Base",Benefits!$CS:$CS,$A30) -> 0.48166667 | AJ30: =SUMIFS(Benefits!$BF:$BF,Benefits!$E:$E,"Gross Margin",Benefits!$F:$F,"USD",Benefits!$D:$D,"Plan Base",Benefits!$CS:$CS,$A30) -> 0.48166667 | AK30: =SUMIFS(Benefits!$BG:$BG,Benefits!$E:$E,"Gross Margin",Benefits!$F:$F,"USD",Benefits!$D:$D,"Plan Base",Benefits!$CS:$CS,$A30) -> 0.48166667 | AL30: =SUMIFS(Benefits!$BH:$BH,Benefits!$E:$E,"Gross Margin",Benefits!$F:$F,"USD",Benefits!$D:$D,"Plan Base",Benefits!$CS:$CS,$A30) -> 0.48166667 | AM30: =SUMIFS(Benefits!$BI:$BI,Benefits!$E:$E,"Gross Margin",Benefits!$F:$F,"USD",Benefits!$D:$D,"Plan Base",Benefits!$CS:$CS,$A30) -> 0.48166667 | AN30: =SUMIFS(Benefits!$BJ:$BJ,Benefits!$E:$E,"Gross Margin",Benefits!$F:$F,"USD",Benefits!$D:$D,"Plan Base",Benefits!$CS:$CS,$A30) -> 0.48166667 | AO30: =SUMIFS(Benefits!$BK:$BK,Benefits!$E:$E,"Gross Margin",Benefits!$F:$F,"USD",Benefits!$D:$D,"Plan Base",Benefits!$CS:$CS,$A30) -> 0.48166667 | AP30: =SUMIFS(Benefits!$BL:$BL,Benefits!$E:$E,"Gross Margin",Benefits!$F:$F,"USD",Benefits!$D:$D,"Plan Base",Benefits!$CS:$CS,$A30) -> 0.48166667 | AQ30: =SUMIFS(Benefits!$BM:$BM,Benefits!$E:$E,"Gross Margin",Benefits!$F:$F,"USD",Benefits!$D:$D,"Plan Base",Benefits!$CS:$CS,$A30) -> 0.48166667 | AR30: =SUMIFS(Benefits!$BN:$BN,Benefits!$E:$E,"Gross Margin",Benefits!$F:$F,"USD",Benefits!$D:$D,"Plan Base",Benefits!$CS:$CS,$A30) -> 0.48166667 | AS30: =SUMIFS(Benefits!$BO:$BO,Benefits!$E:$E,"Gross Margin",Benefits!$F:$F,"USD",Benefits!$D:$D,"Plan Base",Benefits!$CS:$CS,$A30) -> 0.48166667 | AT30: =SUMIFS(Benefits!$BP:$BP,Benefits!$E:$E,"Gross Margin",Benefits!$F:$F,"USD",Benefits!$D:$D,"Plan Base",Benefits!$CS:$CS,$A30) -> 0.48166667 | AU30: =SUMIFS(Benefits!$BQ:$BQ,Benefits!$E:$E,"Gross Margin",Benefits!$F:$F,"USD",Benefits!$D:$D,"Plan Base",Benefits!$CS:$CS,$A30) -> 0.48166667 | AV30: =SUMIFS(Benefits!$BR:$BR,Benefits!$E:$E,"Gross Margin",Benefits!$F:$F,"USD",Benefits!$D:$D,"Plan Base",Benefits!$CS:$CS,$A30) -> 0.48166667 | AW30: =SUMIFS(Benefits!$BS:$BS,Benefits!$E:$E,"Gross Margin",Benefits!$F:$F,"USD",Benefits!$D:$D,"Plan Base",Benefits!$CS:$CS,$A30) -> 0.48166667 | AX30: =SUMIFS(Benefits!$BT:$BT,Benefits!$E:$E,"Gross Margin",Benefits!$F:$F,"USD",Benefits!$D:$D,"Plan Base",Benefits!$CS:$CS,$A30) -> 0.48166667 | AY30: =SUMIFS(Benefits!$BU:$BU,Benefits!$E:$E,"Gross Margin",Benefits!$F:$F,"USD",Benefits!$D:$D,"Plan Base",Benefits!$CS:$CS,$A30) -> 0.48166667 | AZ30: =SUMIFS(Benefits!$BV:$BV,Benefits!$E:$E,"Gross Margin",Benefits!$F:$F,"USD",Benefits!$D:$D,"Plan Base",Benefits!$CS:$CS,$A30) -> 0.48166667 | BA30: =SUMIFS(Benefits!$BW:$BW,Benefits!$E:$E,"Gross Margin",Benefits!$F:$F,"USD",Benefits!$D:$D,"Plan Base",Benefits!$CS:$CS,$A30) -> 0.48166667 | BB30: =SUMIFS(Benefits!$BX:$BX,Benefits!$E:$E,"Gross Margin",Benefits!$F:$F,"USD",Benefits!$D:$D,"Plan Base",Benefits!$CS:$CS,$A30) -> 0.48166667 | BC30: =SUMIFS(Benefits!$BY:$BY,Benefits!$E:$E,"Gross Margin",Benefits!$F:$F,"USD",Benefits!$D:$D,"Plan Base",Benefits!$CS:$CS,$A30) -> 0.48166667 | BD30: =SUMIFS(Benefits!$BZ:$BZ,Benefits!$E:$E,"Gross Margin",Benefits!$F:$F,"USD",Benefits!$D:$D,"Plan Base",Benefits!$CS:$CS,$A30) -> 0.48166667 | BE30: =SUMIFS(Benefits!$CA:$CA,Benefits!$E:$E,"Gross Margin",Benefits!$F:$F,"USD",Benefits!$D:$D,"Plan Base",Benefits!$CS:$CS,$A30) -> 0.48166667 | BF30: =SUMIFS(Benefits!$CB:$CB,Benefits!$E:$E,"Gross Margin",Benefits!$F:$F,"USD",Benefits!$D:$D,"Plan Base",Benefits!$CS:$CS,$A30) -> 0.48166667 | BG30: =SUMIFS(Benefits!$CC:$CC,Benefits!$E:$E,"Gross Margin",Benefits!$F:$F,"USD",Benefits!$D:$D,"Plan Base",Benefits!$CS:$CS,$A30) -> 0.48166667 | BH30: =SUMIFS(Benefits!$CD:$CD,Benefits!$E:$E,"Gross Margin",Benefits!$F:$F,"USD",Benefits!$D:$D,"Plan Base",Benefits!$CS:$CS,$A30) -> 0.48166667 | BI30: =SUMIFS(Benefits!$CE:$CE,Benefits!$E:$E,"Gross Margin",Benefits!$F:$F,"USD",Benefits!$D:$D,"Plan Base",Benefits!$CS:$CS,$A30) -> 0.48166667
A31: Eastbridge Region | B31: =SUMIFS(Benefits!$S:$S,Benefits!$E:$E,"Gross Margin",Benefits!$F:$F,"USD",Benefits!$D:$D,"Plan Base",Benefits!$CS:$CS,$A31) -> 1.116 | C31: =SUMIFS(Benefits!$T:$T,Benefits!$E:$E,"Gross Margin",Benefits!$F:$F,"USD",Benefits!$D:$D,"Plan Base",Benefits!$CS:$CS,$A31) -> 3.577 | D31: =SUMIFS(Benefits!$U:$U,Benefits!$E:$E,"Gross Margin",Benefits!$F:$F,"USD",Benefits!$D:$D,"Plan Base",Benefits!$CS:$CS,$A31) -> 5.567 | E31: =SUMIFS(Benefits!$V:$V,Benefits!$E:$E,"Gross Margin",Benefits!$F:$F,"USD",Benefits!$D:$D,"Plan Base",Benefits!$CS:$CS,$A31) -> 5.567 | F31: =SUMIFS(Benefits!$W:$W,Benefits!$E:$E,"Gross Margin",Benefits!$F:$F,"USD",Benefits!$D:$D,"Plan Base",Benefits!$CS:$CS,$A31) -> 5.567 | H31: =SUMIFS(Benefits!$AD:$AD,Benefits!$E:$E,"Gross Margin",Benefits!$F:$F,"USD",Benefits!$D:$D,"Plan Base",Benefits!$CS:$CS,$A31) -> 0 | I31: =SUMIFS(Benefits!$AE:$AE,Benefits!$E:$E,"Gross Margin",Benefits!$F:$F,"USD",Benefits!$D:$D,"Plan Base",Benefits!$CS:$CS,$A31) -> 0 | J31: =SUMIFS(Benefits!$AF:$AF,Benefits!$E:$E,"Gross Margin",Benefits!$F:$F,"USD",Benefits!$D:$D,"Plan Base",Benefits!$CS:$CS,$A31) -> 0 | K31: =SUMIFS(Benefits!$AG:$AG,Benefits!$E:$E,"Gross Margin",Benefits!$F:$F,"USD",Benefits!$D:$D,"Plan Base",Benefits!$CS:$CS,$A31) -> 0.372 | L31: =SUMIFS(Benefits!$AH:$AH,Benefits!$E:$E,"Gross Margin",Benefits!$F:$F,"USD",Benefits!$D:$D,"Plan Base",Benefits!$CS:$CS,$A31) -> 0.372 | M31: =SUMIFS(Benefits!$AI:$AI,Benefits!$E:$E,"Gross Margin",Benefits!$F:$F,"USD",Benefits!$D:$D,"Plan Base",Benefits!$CS:$CS,$A31) -> 0.372 | N31: =SUMIFS(Benefits!$AJ:$AJ,Benefits!$E:$E,"Gross Margin",Benefits!$F:$F,"USD",Benefits!$D:$D,"Plan Base",Benefits!$CS:$CS,$A31) -> 0.1395 | O31: =SUMIFS(Benefits!$AK:$AK,Benefits!$E:$E,"Gross Margin",Benefits!$F:$F,"USD",Benefits!$D:$D,"Plan Base",Benefits!$CS:$CS,$A31) -> 0.1395 | P31: =SUMIFS(Benefits!$AL:$AL,Benefits!$E:$E,"Gross Margin",Benefits!$F:$F,"USD",Benefits!$D:$D,"Plan Base",Benefits!$CS:$CS,$A31) -> 0.1395 | Q31: =SUMIFS(Benefits!$AM:$AM,Benefits!$E:$E,"Gross Margin",Benefits!$F:$F,"USD",Benefits!$D:$D,"Plan Base",Benefits!$CS:$CS,$A31) -> 0.19083333 | R31: =SUMIFS(Benefits!$AN:$AN,Benefits!$E:$E,"Gross Margin",Benefits!$F:$F,"USD",Benefits!$D:$D,"Plan Base",Benefits!$CS:$CS,$A31) -> 0.19083333 | S31: =SUMIFS(Benefits!$AO:$AO,Benefits!$E:$E,"Gross Margin",Benefits!$F:$F,"USD",Benefits!$D:$D,"Plan Base",Benefits!$CS:$CS,$A31) -> 0.19083333 | T31: =SUMIFS(Benefits!$AP:$AP,Benefits!$E:$E,"Gross Margin",Benefits!$F:$F,"USD",Benefits!$D:$D,"Plan Base",Benefits!$CS:$CS,$A31) -> 0.28283333 | U31: =SUMIFS(Benefits!$AQ:$AQ,Benefits!$E:$E,"Gross Margin",Benefits!$F:$F,"USD",Benefits!$D:$D,"Plan Base",Benefits!$CS:$CS,$A31) -> 0.28283333 | V31: =SUMIFS(Benefits!$AR:$AR,Benefits!$E:$E,"Gross Margin",Benefits!$F:$F,"USD",Benefits!$D:$D,"Plan Base",Benefits!$CS:$CS,$A31) -> 0.34233333 | W31: =SUMIFS(Benefits!$AS:$AS,Benefits!$E:$E,"Gross Margin",Benefits!$F:$F,"USD",Benefits!$D:$D,"Plan Base",Benefits!$CS:$CS,$A31) -> 0.34233333 | X31: =SUMIFS(Benefits!$AT:$AT,Benefits!$E:$E,"Gross Margin",Benefits!$F:$F,"USD",Benefits!$D:$D,"Plan Base",Benefits!$CS:$CS,$A31) -> 0.34233333 | Y31: =SUMIFS(Benefits!$AU:$AU,Benefits!$E:$E,"Gross Margin",Benefits!$F:$F,"USD",Benefits!$D:$D,"Plan Base",Benefits!$CS:$CS,$A31) -> 0.99333333 | Z31: =SUMIFS(Benefits!$AV:$AV,Benefits!$E:$E,"Gross Margin",Benefits!$F:$F,"USD",Benefits!$D:$D,"Plan Base",Benefits!$CS:$CS,$A31) -> 0.46391667 | AA31: =SUMIFS(Benefits!$AW:$AW,Benefits!$E:$E,"Gross Margin",Benefits!$F:$F,"USD",Benefits!$D:$D,"Plan Base",Benefits!$CS:$CS,$A31) -> 0.46391667 | AB31: =SUMIFS(Benefits!$AX:$AX,Benefits!$E:$E,"Gross Margin",Benefits!$F:$F,"USD",Benefits!$D:$D,"Plan Base",Benefits!$CS:$CS,$A31) -> 0.46391667 | AC31: =SUMIFS(Benefits!$AY:$AY,Benefits!$E:$E,"Gross Margin",Benefits!$F:$F,"USD",Benefits!$D:$D,"Plan Base",Benefits!$CS:$CS,$A31) -> 0.46391667 | AD31: =SUMIFS(Benefits!$AZ:$AZ,Benefits!$E:$E,"Gross Margin",Benefits!$F:$F,"USD",Benefits!$D:$D,"Plan Base",Benefits!$CS:$CS,$A31) -> 0.46391667 | AE31: =SUMIFS(Benefits!$BA:$BA,Benefits!$E:$E,"Gross Margin",Benefits!$F:$F,"USD",Benefits!$D:$D,"Plan Base",Benefits!$CS:$CS,$A31) -> 0.46391667 | AF31: =SUMIFS(Benefits!$BB:$BB,Benefits!$E:$E,"Gross Margin",Benefits!$F:$F,"USD",Benefits!$D:$D,"Plan Base",Benefits!$CS:$CS,$A31) -> 0.46391667 | AG31: =SUMIFS(Benefits!$BC:$BC,Benefits!$E:$E,"Gross Margin",Benefits!$F:$F,"USD",Benefits!$D:$D,"Plan Base",Benefits!$CS:$CS,$A31) -> 0.46391667 | AH31: =SUMIFS(Benefits!$BD:$BD,Benefits!$E:$E,"Gross Margin",Benefits!$F:$F,"USD",Benefits!$D:$D,"Plan Base",Benefits!$CS:$CS,$A31) -> 0.46391667 | AI31: =SUMIFS(Benefits!$BE:$BE,Benefits!$E:$E,"Gross Margin",Benefits!$F:$F,"USD",Benefits!$D:$D,"Plan Base",Benefits!$CS:$CS,$A31) -> 0.46391667 | AJ31: =SUMIFS(Benefits!$BF:$BF,Benefits!$E:$E,"Gross Margin",Benefits!$F:$F,"USD",Benefits!$D:$D,"Plan Base",Benefits!$CS:$CS,$A31) -> 0.46391667 | AK31: =SUMIFS(Benefits!$BG:$BG,Benefits!$E:$E,"Gross Margin",Benefits!$F:$F,"USD",Benefits!$D:$D,"Plan Base",Benefits!$CS:$CS,$A31) -> 0.46391667 | AL31: =SUMIFS(Benefits!$BH:$BH,Benefits!$E:$E,"Gross Margin",Benefits!$F:$F,"USD",Benefits!$D:$D,"Plan Base",Benefits!$CS:$CS,$A31) -> 0.46391667 | AM31: =SUMIFS(Benefits!$BI:$BI,Benefits!$E:$E,"Gross Margin",Benefits!$F:$F,"USD",Benefits!$D:$D,"Plan Base",Benefits!$CS:$CS,$A31) -> 0.46391667 | AN31: =SUMIFS(Benefits!$BJ:$BJ,Benefits!$E:$E,"Gross Margin",Benefits!$F:$F,"USD",Benefits!$D:$D,"Plan Base",Benefits!$CS:$CS,$A31) -> 0.46391667 | AO31: =SUMIFS(Benefits!$BK:$BK,Benefits!$E:$E,"Gross Margin",Benefits!$F:$F,"USD",Benefits!$D:$D,"Plan Base",Benefits!$CS:$CS,$A31) -> 0.46391667 | AP31: =SUMIFS(Benefits!$BL:$BL,Benefits!$E:$E,"Gross Margin",Benefits!$F:$F,"USD",Benefits!$D:$D,"Plan Base",Benefits!$CS:$CS,$A31) -> 0.46391667 | AQ31: =SUMIFS(Benefits!$BM:$BM,Benefits!$E:$E,"Gross Margin",Benefits!$F:$F,"USD",Benefits!$D:$D,"Plan Base",Benefits!$CS:$CS,$A31) -> 0.46391667 | AR31: =SUMIFS(Benefits!$BN:$BN,Benefits!$E:$E,"Gross Margin",Benefits!$F:$F,"USD",Benefits!$D:$D,"Plan Base",Benefits!$CS:$CS,$A31) -> 0.46391667 | AS31: =SUMIFS(Benefits!$BO:$BO,Benefits!$E:$E,"Gross Margin",Benefits!$F:$F,"USD",Benefits!$D:$D,"Plan Base",Benefits!$CS:$CS,$A31) -> 0.46391667 | AT31: =SUMIFS(Benefits!$BP:$BP,Benefits!$E:$E,"Gross Margin",Benefits!$F:$F,"USD",Benefits!$D:$D,"Plan Base",Benefits!$CS:$CS,$A31) -> 0.46391667 | AU31: =SUMIFS(Benefits!$BQ:$BQ,Benefits!$E:$E,"Gross Margin",Benefits!$F:$F,"USD",Benefits!$D:$D,"Plan Base",Benefits!$CS:$CS,$A31) -> 0.46391667 | AV31: =SUMIFS(Benefits!$BR:$BR,Benefits!$E:$E,"Gross Margin",Benefits!$F:$F,"USD",Benefits!$D:$D,"Plan Base",Benefits!$CS:$CS,$A31) -> 0.46391667 | AW31: =SUMIFS(Benefits!$BS:$BS,Benefits!$E:$E,"Gross Margin",Benefits!$F:$F,"USD",Benefits!$D:$D,"Plan Base",Benefits!$CS:$CS,$A31) -> 0.46391667 | AX31: =SUMIFS(Benefits!$BT:$BT,Benefits!$E:$E,"Gross Margin",Benefits!$F:$F,"USD",Benefits!$D:$D,"Plan Base",Benefits!$CS:$CS,$A31) -> 0.46391667 | AY31: =SUMIFS(Benefits!$BU:$BU,Benefits!$E:$E,"Gross Margin",Benefits!$F:$F,"USD",Benefits!$D:$D,"Plan Base",Benefits!$CS:$CS,$A31) -> 0.46391667 | AZ31: =SUMIFS(Benefits!$BV:$BV,Benefits!$E:$E,"Gross Margin",Benefits!$F:$F,"USD",Benefits!$D:$D,"Plan Base",Benefits!$CS:$CS,$A31) -> 0.46391667 | BA31: =SUMIFS(Benefits!$BW:$BW,Benefits!$E:$E,"Gross Margin",Benefits!$F:$F,"USD",Benefits!$D:$D,"Plan Base",Benefits!$CS:$CS,$A31) -> 0.46391667 | BB31: =SUMIFS(Benefits!$BX:$BX,Benefits!$E:$E,"Gross Margin",Benefits!$F:$F,"USD",Benefits!$D:$D,"Plan Base",Benefits!$CS:$CS,$A31) -> 0.46391667 | BC31: =SUMIFS(Benefits!$BY:$BY,Benefits!$E:$E,"Gross Margin",Benefits!$F:$F,"USD",Benefits!$D:$D,"Plan Base",Benefits!$CS:$CS,$A31) -> 0.46391667 | BD31: =SUMIFS(Benefits!$BZ:$BZ,Benefits!$E:$E,"Gross Margin",Benefits!$F:$F,"USD",Benefits!$D:$D,"Plan Base",Benefits!$CS:$CS,$A31) -> 0.46391667 | BE31: =SUMIFS(Benefits!$CA:$CA,Benefits!$E:$E,"Gross Margin",Benefits!$F:$F,"USD",Benefits!$D:$D,"Plan Base",Benefits!$CS:$CS,$A31) -> 0.46391667 | BF31: =SUMIFS(Benefits!$CB:$CB,Benefits!$E:$E,"Gross Margin",Benefits!$F:$F,"USD",Benefits!$D:$D,"Plan Base",Benefits!$CS:$CS,$A31) -> 0.46391667 | BG31: =SUMIFS(Benefits!$CC:$CC,Benefits!$E:$E,"Gross Margin",Benefits!$F:$F,"USD",Benefits!$D:$D,"Plan Base",Benefits!$CS:$CS,$A31) -> 0.46391667 | BH31: =SUMIFS(Benefits!$CD:$CD,Benefits!$E:$E,"Gross Margin",Benefits!$F:$F,"USD",Benefits!$D:$D,"Plan Base",Benefits!$CS:$CS,$A31) -> 0.46391667 | BI31: =SUMIFS(Benefits!$CE:$CE,Benefits!$E:$E,"Gross Margin",Benefits!$F:$F,"USD",Benefits!$D:$D,"Plan Base",Benefits!$CS:$CS,$A31) -> 0.46391667
